<?xml version="1.0" encoding="UTF-8"?>
<testng-results ignored="0" total="3" passed="0" failed="3" skipped="0">
  <reporter-output>
  </reporter-output>
  <suite started-at="2022-03-24T14:19:22 CET" name="Failed suite [InetBanking]" finished-at="2022-03-24T14:20:14 CET" duration-ms="52439">
    <groups>
    </groups>
    <test started-at="2022-03-24T14:19:22 CET" name="BankingApp Test(failed)" finished-at="2022-03-24T14:20:14 CET" duration-ms="52439">
      <class name="com.inetbanking.testCases.TC_LoginDDT_002">
        <test-method is-config="true" signature="setup(java.lang.String)[pri:0, instance:com.inetbanking.testCases.TC_LoginDDT_002@4803b726]" started-at="2022-03-24T14:19:23 CET" name="setup" finished-at="2022-03-24T14:19:44 CET" duration-ms="21391" status="PASS">
          <params>
            <param index="0">
              <value>
                <![CDATA[chrome]]>
              </value>
            </param>
          </params>
          <reporter-output>
          </reporter-output>
        </test-method> <!-- setup -->
        <test-method signature="loginDDT(java.lang.String, java.lang.String)[pri:0, instance:com.inetbanking.testCases.TC_LoginDDT_002@4803b726]" started-at="2022-03-24T14:19:47 CET" name="loginDDT" data-provider="LoginData" finished-at="2022-03-24T14:19:56 CET" duration-ms="9660" status="FAIL">
          <params>
            <param index="0">
              <value>
                <![CDATA[mngr83460]]>
              </value>
            </param>
            <param index="1">
              <value>
                <![CDATA[qAbUzyj]]>
              </value>
            </param>
          </params>
          <exception class="java.lang.AssertionError">
            <message>
              <![CDATA[expected [true] but found [false]]]>
            </message>
            <full-stacktrace>
              <![CDATA[java.lang.AssertionError: expected [true] but found [false]
at org.testng.Assert.fail(Assert.java:97)
at org.testng.Assert.failNotEquals(Assert.java:969)
at org.testng.Assert.assertTrue(Assert.java:43)
at org.testng.Assert.assertTrue(Assert.java:53)
at com.inetbanking.testCases.TC_LoginDDT_002.loginDDT(TC_LoginDDT_002.java:34)
at java.base/jdk.internal.reflect.NativeMethodAccessorImpl.invoke0(Native Method)
at java.base/jdk.internal.reflect.NativeMethodAccessorImpl.invoke(NativeMethodAccessorImpl.java:77)
at java.base/jdk.internal.reflect.DelegatingMethodAccessorImpl.invoke(DelegatingMethodAccessorImpl.java:43)
at java.base/java.lang.reflect.Method.invoke(Method.java:568)
at org.testng.internal.MethodInvocationHelper.invokeMethod(MethodInvocationHelper.java:134)
at org.testng.internal.TestInvoker.invokeMethod(TestInvoker.java:597)
at org.testng.internal.TestInvoker.invokeTestMethod(TestInvoker.java:173)
at org.testng.internal.MethodRunner.runInSequence(MethodRunner.java:46)
at org.testng.internal.TestInvoker$MethodInvocationAgent.invoke(TestInvoker.java:816)
at org.testng.internal.TestInvoker.invokeTestMethods(TestInvoker.java:146)
at org.testng.internal.TestMethodWorker.invokeTestMethods(TestMethodWorker.java:146)
at org.testng.internal.TestMethodWorker.run(TestMethodWorker.java:128)
at java.base/java.util.ArrayList.forEach(ArrayList.java:1511)
at org.testng.TestRunner.privateRun(TestRunner.java:766)
at org.testng.TestRunner.run(TestRunner.java:587)
at org.testng.SuiteRunner.runTest(SuiteRunner.java:384)
at org.testng.SuiteRunner.runSequentially(SuiteRunner.java:378)
at org.testng.SuiteRunner.privateRun(SuiteRunner.java:337)
at org.testng.SuiteRunner.run(SuiteRunner.java:286)
at org.testng.SuiteRunnerWorker.runSuite(SuiteRunnerWorker.java:53)
at org.testng.SuiteRunnerWorker.run(SuiteRunnerWorker.java:96)
at org.testng.TestNG.runSuitesSequentially(TestNG.java:1187)
at org.testng.TestNG.runSuitesLocally(TestNG.java:1109)
at org.testng.TestNG.runSuites(TestNG.java:1039)
at org.testng.TestNG.run(TestNG.java:1007)
at org.testng.remote.AbstractRemoteTestNG.run(AbstractRemoteTestNG.java:115)
at org.testng.remote.RemoteTestNG.initAndRun(RemoteTestNG.java:251)
at org.testng.remote.RemoteTestNG.main(RemoteTestNG.java:77)
]]>
            </full-stacktrace>
          </exception> <!-- java.lang.AssertionError -->
          <reporter-output>
          </reporter-output>
        </test-method> <!-- loginDDT -->
        <test-method signature="loginDDT(java.lang.String, java.lang.String)[pri:0, instance:com.inetbanking.testCases.TC_LoginDDT_002@4803b726]" started-at="2022-03-24T14:19:56 CET" name="loginDDT" data-provider="LoginData" finished-at="2022-03-24T14:20:06 CET" duration-ms="9238" status="FAIL">
          <params>
            <param index="0">
              <value>
                <![CDATA[mngr164225]]>
              </value>
            </param>
            <param index="1">
              <value>
                <![CDATA[jahetAp]]>
              </value>
            </param>
          </params>
          <exception class="java.lang.AssertionError">
            <message>
              <![CDATA[expected [true] but found [false]]]>
            </message>
            <full-stacktrace>
              <![CDATA[java.lang.AssertionError: expected [true] but found [false]
at org.testng.Assert.fail(Assert.java:97)
at org.testng.Assert.failNotEquals(Assert.java:969)
at org.testng.Assert.assertTrue(Assert.java:43)
at org.testng.Assert.assertTrue(Assert.java:53)
at com.inetbanking.testCases.TC_LoginDDT_002.loginDDT(TC_LoginDDT_002.java:34)
at java.base/jdk.internal.reflect.NativeMethodAccessorImpl.invoke0(Native Method)
at java.base/jdk.internal.reflect.NativeMethodAccessorImpl.invoke(NativeMethodAccessorImpl.java:77)
at java.base/jdk.internal.reflect.DelegatingMethodAccessorImpl.invoke(DelegatingMethodAccessorImpl.java:43)
at java.base/java.lang.reflect.Method.invoke(Method.java:568)
at org.testng.internal.MethodInvocationHelper.invokeMethod(MethodInvocationHelper.java:134)
at org.testng.internal.TestInvoker.invokeMethod(TestInvoker.java:597)
at org.testng.internal.TestInvoker.invokeTestMethod(TestInvoker.java:173)
at org.testng.internal.MethodRunner.runInSequence(MethodRunner.java:46)
at org.testng.internal.TestInvoker$MethodInvocationAgent.invoke(TestInvoker.java:816)
at org.testng.internal.TestInvoker.invokeTestMethods(TestInvoker.java:146)
at org.testng.internal.TestMethodWorker.invokeTestMethods(TestMethodWorker.java:146)
at org.testng.internal.TestMethodWorker.run(TestMethodWorker.java:128)
at java.base/java.util.ArrayList.forEach(ArrayList.java:1511)
at org.testng.TestRunner.privateRun(TestRunner.java:766)
at org.testng.TestRunner.run(TestRunner.java:587)
at org.testng.SuiteRunner.runTest(SuiteRunner.java:384)
at org.testng.SuiteRunner.runSequentially(SuiteRunner.java:378)
at org.testng.SuiteRunner.privateRun(SuiteRunner.java:337)
at org.testng.SuiteRunner.run(SuiteRunner.java:286)
at org.testng.SuiteRunnerWorker.runSuite(SuiteRunnerWorker.java:53)
at org.testng.SuiteRunnerWorker.run(SuiteRunnerWorker.java:96)
at org.testng.TestNG.runSuitesSequentially(TestNG.java:1187)
at org.testng.TestNG.runSuitesLocally(TestNG.java:1109)
at org.testng.TestNG.runSuites(TestNG.java:1039)
at org.testng.TestNG.run(TestNG.java:1007)
at org.testng.remote.AbstractRemoteTestNG.run(AbstractRemoteTestNG.java:115)
at org.testng.remote.RemoteTestNG.initAndRun(RemoteTestNG.java:251)
at org.testng.remote.RemoteTestNG.main(RemoteTestNG.java:77)
]]>
            </full-stacktrace>
          </exception> <!-- java.lang.AssertionError -->
          <reporter-output>
          </reporter-output>
        </test-method> <!-- loginDDT -->
        <test-method signature="loginDDT(java.lang.String, java.lang.String)[pri:0, instance:com.inetbanking.testCases.TC_LoginDDT_002@4803b726]" started-at="2022-03-24T14:20:06 CET" name="loginDDT" data-provider="LoginData" finished-at="2022-03-24T14:20:13 CET" duration-ms="7787" status="FAIL">
          <params>
            <param index="0">
              <value>
                <![CDATA[mngr112909]]>
              </value>
            </param>
            <param index="1">
              <value>
                <![CDATA[tytUreg]]>
              </value>
            </param>
          </params>
          <exception class="java.lang.AssertionError">
            <message>
              <![CDATA[expected [true] but found [false]]]>
            </message>
            <full-stacktrace>
              <![CDATA[java.lang.AssertionError: expected [true] but found [false]
at org.testng.Assert.fail(Assert.java:97)
at org.testng.Assert.failNotEquals(Assert.java:969)
at org.testng.Assert.assertTrue(Assert.java:43)
at org.testng.Assert.assertTrue(Assert.java:53)
at com.inetbanking.testCases.TC_LoginDDT_002.loginDDT(TC_LoginDDT_002.java:34)
at java.base/jdk.internal.reflect.NativeMethodAccessorImpl.invoke0(Native Method)
at java.base/jdk.internal.reflect.NativeMethodAccessorImpl.invoke(NativeMethodAccessorImpl.java:77)
at java.base/jdk.internal.reflect.DelegatingMethodAccessorImpl.invoke(DelegatingMethodAccessorImpl.java:43)
at java.base/java.lang.reflect.Method.invoke(Method.java:568)
at org.testng.internal.MethodInvocationHelper.invokeMethod(MethodInvocationHelper.java:134)
at org.testng.internal.TestInvoker.invokeMethod(TestInvoker.java:597)
at org.testng.internal.TestInvoker.invokeTestMethod(TestInvoker.java:173)
at org.testng.internal.MethodRunner.runInSequence(MethodRunner.java:46)
at org.testng.internal.TestInvoker$MethodInvocationAgent.invoke(TestInvoker.java:816)
at org.testng.internal.TestInvoker.invokeTestMethods(TestInvoker.java:146)
at org.testng.internal.TestMethodWorker.invokeTestMethods(TestMethodWorker.java:146)
at org.testng.internal.TestMethodWorker.run(TestMethodWorker.java:128)
at java.base/java.util.ArrayList.forEach(ArrayList.java:1511)
at org.testng.TestRunner.privateRun(TestRunner.java:766)
at org.testng.TestRunner.run(TestRunner.java:587)
at org.testng.SuiteRunner.runTest(SuiteRunner.java:384)
at org.testng.SuiteRunner.runSequentially(SuiteRunner.java:378)
at org.testng.SuiteRunner.privateRun(SuiteRunner.java:337)
at org.testng.SuiteRunner.run(SuiteRunner.java:286)
at org.testng.SuiteRunnerWorker.runSuite(SuiteRunnerWorker.java:53)
at org.testng.SuiteRunnerWorker.run(SuiteRunnerWorker.java:96)
at org.testng.TestNG.runSuitesSequentially(TestNG.java:1187)
at org.testng.TestNG.runSuitesLocally(TestNG.java:1109)
at org.testng.TestNG.runSuites(TestNG.java:1039)
at org.testng.TestNG.run(TestNG.java:1007)
at org.testng.remote.AbstractRemoteTestNG.run(AbstractRemoteTestNG.java:115)
at org.testng.remote.RemoteTestNG.initAndRun(RemoteTestNG.java:251)
at org.testng.remote.RemoteTestNG.main(RemoteTestNG.java:77)
]]>
            </full-stacktrace>
          </exception> <!-- java.lang.AssertionError -->
          <reporter-output>
          </reporter-output>
        </test-method> <!-- loginDDT -->
        <test-method is-config="true" signature="tearDown()[pri:0, instance:com.inetbanking.testCases.TC_LoginDDT_002@4803b726]" started-at="2022-03-24T14:20:13 CET" name="tearDown" finished-at="2022-03-24T14:20:14 CET" duration-ms="703" status="PASS">
          <reporter-output>
          </reporter-output>
        </test-method> <!-- tearDown -->
      </class> <!-- com.inetbanking.testCases.TC_LoginDDT_002 -->
    </test> <!-- BankingApp Test(failed) -->
  </suite> <!-- Failed suite [InetBanking] -->
</testng-results>
